Workbook

Sheet README
A1: ExitBlueprint — Bootstrap Cash Flow Model (v6)
A4: THESIS
A5: Bootstrap ExitBlueprint on a small founder loan from Joe. No SBA loan, no Series A raise.
A6: Joe lends the company just enough to bridge the pre-revenue burn; the loan is repaid from
A7: operating cash flow as advisors ramp. Founders draw only once the business can fund it.
A9: HOW THE BOOTSTRAP WORKS
A10: 1. Joe funds a $55k loan at Mo 0 (Aug-26) — sized to the deepest cash hole (~$39k) + a $15k buffer.
A11: 2. Interest accrues (non-cash) while pre-revenue; nothing is paid out during the burn.
A12: 3. GTM right after Labor Day (Mo 1 = Sep-26). Founding advisors onboard; revenue begins.
A13: 4. Founder draws ($5k/mo) switch on only when gross profit covers them (Mo 3, Nov-26).
A14: 5. Once monthly cash flow turns positive (Mo 4), surplus above the buffer sweeps back to Joe.
A15: 6. Joe is fully repaid by ~Mo 7 (Mar-27) with ~$1.9k total interest. Business self-funds thereafter.
... A36: independently verified cell-by-cell before delivery.

Sheet Assumptions
A1: ExitBlueprint — Assumptions (Bootstrap Plan)
A2: Edit BLUE cells to run scenarios. All other sheets pull from here. YELLOW = key lever.
A3: CAPITAL STRUCTURE — BOOTSTRAP LOAN FROM JOE
A4: Joe bootstrap loan — principal | B4: 55000 | C4: Sized to peak cash trough (-$39k, Mo 3) + buffer. Founder loan, no equity taken.
A5: Joe loan — annual interest rate | B5: 0.06 | C5: Founder-friendly; keep >= IRS AFR to avoid imputed interest. Accrues until repaid.
A6: Joe loan — funding month (index) | B6: 0 | C6: Mo 0 = Aug 2026 (on signing)
A7: Minimum cash buffer to hold | B7: 15000 | C7: Repayment sweep never draws ending cash below this floor.
A8: Repay Joe from surplus cash? (1=yes,0=no) | B8: 1 | C8: When on, surplus above buffer sweeps to repay Joe (principal+accrued interest).
A10: FOUNDER COMPENSATION
A11: Founder draw target — Matthew ($/mo) | B11: 5000 | C11: Draws are OFF until gross profit >= this amount (see trigger).
A12: Draw trigger: gross profit (MRR less processing) >= draw target | C12: So a draw never pushes cash negative on its own. Latches ON once met.
A13: Joe deferred comp — accrued, NON-CASH ($/mo) | B13: 0 | C13: Tracked on the books, not paid in cash. Default 0; Joe's stake is the loan.
A15: PRE-LAUNCH ONE-TIME COSTS (Mo 0)
A16: Legal — Entity formation & filing | B16: 1500 | C16: LLC/Corp setup, EIN, state filings
A17: Legal — Operating Agreement | B17: 3000 | C17: Multi-member OA incl. Joe loan terms
A18: Legal — Trademark / IP | B18: 3500 | C18: Mark search + USPTO filing; IP assignment
A19: Legal — Terms of Service / Privacy Policy | B19: 2000 | C19: ToS, Privacy, DPA templates
A20: SOC 2 — Year 1 setup (all-in) | B20: 20000 | C20: Spread over first months (below)
A21: SOC 2 setup — months to spread over | B21: 3 | C21: Mo 0-2
A23: MONTHLY RECURRING — FIXED (LEAN)
A24: Bloom Growth (EOS platform) | B24: 299 | C24: Ops/planning platform
A25: SOC 2 platform (annual / 12) | B25: 1667 | C25: Compliance tooling amortized monthly
A27: SCALE-DRIVEN OPEX — TIERS
A28: Hosting / Infrastructure (by total advisors)
A29: Hosting T1: 0-50 advisors | B29: 500 | C29: Basic cloud
A30: Hosting T2: 51-150 | B30: 1500 | C30: Scaled compute + backups
A31: Hosting T3: 151-500 | B31: 3000 | C31: Auto-scaling infra
A32: Hosting T4: 501+ | B32: 8000 | C32: Enterprise-grade
A33: Contractor / Intern pool (by total advisors)
A34: Pool T1: 0-25 advisors | B34: 0 | C34: Founder covers; no spend pre-traction
A35: Pool T2: 26-100 | B35: 1500 | C35: ~75 hrs/mo support & onboarding
A36: Pool T3: 101-300 | B36: 3500 | C36: Dedicated part-time support
A37: Pool T4: 301+ | B37: 6000 | C37: Near-FTE contractor coverage
A38: Customer Success & Support (by month)
A39: CS&Support Phase 0: Mo 0-5 | B39: 0 | C39: Founder + tools cover
A40: CS&Support Phase 1: Mo 6-11 | B40: 1500 | C40: Part-time contractor + helpdesk tools
A41: CS&Support Phase 2: Mo 12+ | B41: 3500 | C41: Support lead as base scales
A42: Tools / SaaS stack (by month)
A43: Tools Phase 0: Mo 0-5 | B43: 500 | C43: Hosting-adjacent, monitoring, comms
A44: Tools Phase 1: Mo 6+ | B44: 1000 | C44: Analytics, CRM, expanded stack
...

Sheet Joe Loan
A1: ExitBlueprint — Joe Bootstrap Loan (Accrual + Cash-Flow Sweep)
A2: Line Item | B2: Mo 0 | C2: Mo 1 | D2: Mo 2 | E2: Mo 3 | F2: Mo 4 | G2: Mo 5 | H2: Mo 6 | I2: Mo 7 | J2: Mo 8 | K2: Mo 9 | L2: Mo 10 | M2: Mo 11 | N2: Mo 12 | O2: Mo 13 | P2: Mo 14 | Q2: Mo 15 | R2: Mo 16 | S2: Mo 17 | T2: Mo 18
A3: Calendar | B3: Aug-26 | C3: Sep-26 | D3: Oct-26 | E3: Nov-26 | F3: Dec-26 | G3: Jan-27 | H3: Feb-27 | I3: Mar-27 | J3: Apr-27 | K3: May-27 | L3: Jun-27 | M3: Jul-27 | N3: Aug-27 | O3: Sep-27 | P3: Oct-27 | Q3: Nov-27 | R3: Dec-27 | S3: Jan-28 | T3: Feb-28
A4: LOAN STRUCTURE (from Assumptions)
A5: Opening Balance | B5: 0 | C5: =B10 -> 55275 | D5: =C10 -> 55551.375 | E5: =D10 -> 55829.132 | F5: =E10 -> 56108.278 | G5: =F10 -> 51014.819 | H5: =G10 -> 36159.893 | I5: =H10 -> 9179.6925 | J5: =I10 -> 0 | ... T5: =S10 -> 0
A6: Drawdown (funding event) | B6: =IF(0=Assumptions!$B$6,Assumptions!$B$4,0) -> 55000 | C6: =IF(1=Assumptions!$B$6,Assumptions!$B$4,0) -> 0 | D6: =IF(2=Assumptions!$B$6,Assumptions!$B$4,0) -> 0 | E6: =IF(3=Assumptions!$B$6,Assumptions!$B$4,0) -> 0 | F6: =IF(4=Assumptions!$B$6,Assumptions!$B$4,0) -> 0 | G6: =IF(5=Assumptions!$B$6,Assumptions!$B$4,0) -> 0 | H6: =IF(6=Assumptions!$B$6,Assumptions!$B$4,0) -> 0 | I6: =IF(7=Assumptions!$B$6,Assumptions!$B$4,0) -> 0 | J6: =IF(8=Assumptions!$B$6,Assumptions!$B$4,0) -> 0 | K6: =IF(9=Assumptions!$B$6,Assumptions!$B$4,0) -> 0 | L6: =IF(10=Assumptions!$B$6,Assumptions!$B$4,0) -> 0 | M6: =IF(11=Assumptions!$B$6,Assumptions!$B$4,0) -> 0 | N6: =IF(12=Assumptions!$B$6,Assumptions!$B$4,0) -> 0 | O6: =IF(13=Assumptions!$B$6,Assumptions!$B$4,0) -> 0 | P6: =IF(14=Assumptions!$B$6,Assumptions!$B$4,0) -> 0 | Q6: =IF(15=Assumptions!$B$6,Assumptions!$B$4,0) -> 0 | R6: =IF(16=Assumptions!$B$6,Assumptions!$B$4,0) -> 0 | S6: =IF(17=Assumptions!$B$6,Assumptions!$B$4,0) -> 0 | T6: =IF(18=Assumptions!$B$6,Assumptions!$B$4,0) -> 0
A7: Interest Accrued (PIK, non-cash) | B7: =IF(0<Assumptions!$B$6,0,(B5+B6)*Assumptions!$B$5/12) -> 275 | C7: =IF(1<Assumptions!$B$6,0,(C5+C6)*Assumptions!$B$5/12) -> 276.375 | D7: =IF(2<Assumptions!$B$6,0,(D5+D6)*Assumptions!$B$5/12) -> 277.75687 | E7: =IF(3<Assumptions!$B$6,0,(E5+E6)*Assumptions!$B$5/12) -> 279.14566 | F7: =IF(4<Assumptions!$B$6,0,(F5+F6)*Assumptions!$B$5/12) -> 280.54139 | G7: =IF(5<Assumptions!$B$6,0,(G5+G6)*Assumptions!$B$5/12) -> 255.07409 | H7: =IF(6<Assumptions!$B$6,0,(H5+H6)*Assumptions!$B$5/12) -> 180.79947 | I7: =IF(7<Assumptions!$B$6,0,(I5+I6)*Assumptions!$B$5/12) -> 45.898462 | J7: =IF(8<Assumptions!$B$6,0,(J5+J6)*Assumptions!$B$5/12) -> 0 | K7: =IF(9<Assumptions!$B$6,0,(K5+K6)*Assumptions!$B$5/12) -> 0 | L7: =IF(10<Assumptions!$B$6,0,(L5+L6)*Assumptions!$B$5/12) -> 0 | M7: =IF(11<Assumptions!$B$6,0,(M5+M6)*Assumptions!$B$5/12) -> 0 | N7: =IF(12<Assumptions!$B$6,0,(N5+N6)*Assumptions!$B$5/12) -> 0 | O7: =IF(13<Assumptions!$B$6,0,(O5+O6)*Assumptions!$B$5/12) -> 0 | P7: =IF(14<Assumptions!$B$6,0,(P5+P6)*Assumptions!$B$5/12) -> 0 | Q7: =IF(15<Assumptions!$B$6,0,(Q5+Q6)*Assumptions!$B$5/12) -> 0 | R7: =IF(16<Assumptions!$B$6,0,(R5+R6)*Assumptions!$B$5/12) -> 0 | S7: =IF(17<Assumptions!$B$6,0,(S5+S6)*Assumptions!$B$5/12) -> 0 | T7: =IF(18<Assumptions!$B$6,0,(T5+T6)*Assumptions!$B$5/12) -> 0
A8: Balance Before Repayment | B8: =B5+B6+B7 -> 55275 | C8: =C5+C6+C7 -> 55551.375 | D8: =D5+D6+D7 -> 55829.132 | E8: =E5+E6+E7 -> 56108.278 | F8: =F5+F6+F7 -> 56388.819 | G8: =G5+G6+G7 -> 51269.893 | H8: =H5+H6+H7 -> 36340.692 | I8: =I5+I6+I7 -> 9225.5909 | ... T8: =T5+T6+T7 -> 0
A9: Repayment — Cash Sweep (from Cash Flow) | B9: ='Monthly Cash Flow'!B53 -> 0 | C9: ='Monthly Cash Flow'!C53 -> 0 | D9: ='Monthly Cash Flow'!D53 -> 0 | E9: ='Monthly Cash Flow'!E53 -> 0 | F9: ='Monthly Cash Flow'!F53 -> 5374 | G9: ='Monthly Cash Flow'!G53 -> 15110 | H9: ='Monthly Cash Flow'!H53 -> 27161 | I9: ='Monthly Cash Flow'!I53 -> 9225.5909 | ... T9: ='Monthly Cash Flow'!T53 -> 0
A10: Closing Balance | B10: =B8-B9 -> 55275 | C10: =C8-C9 -> 55551.375 | D10: =D8-D9 -> 55829.132 | E10: =E8-E9 -> 56108.278 | F10: =F8-F9 -> 51014.819 | G10: =G8-G9 -> 36159.893 | H10: =H8-H9 -> 9179.6925 | I10: =I8-I9 -> 0 | ... T10: =T8-T9 -> 0
A12: CUMULATIVE & METRICS
A13: Cumulative Interest Accrued | B13: =B7 -> 275 | C13: =B13+C7 -> 551.375 | D13: =C13+D7 -> 829.13188 | E13: =D13+E7 -> 1108.2775 | F13: =E13+F7 -> 1388.8189 | G13: =F13+G7 -> 1643.893 | H13: =G13+H7 -> 1824.6925 | I13: =H13+I7 -> 1870.5909 | J13: =I13+J7 -> 1870.5909 | ... T13: =S13+T7 -> 1870.5909
A14: Cumulative Repaid to Joe | B14: =B9 -> 0 | C14: =B14+C9 -> 0 | D14: =C14+D9 -> 0 | E14: =D14+E9 -> 0 | F14: =E14+F9 -> 5374 | G14: =F14+G9 -> 20484 | H14: =G14+H9 -> 47645 | I14: =H14+I9 -> 56870.591 | J14: =I14+J9 -> 56870.591 | ... T14: =S14+T9 -> 56870.591
A15: % of Loan Repaid | B15: =IFERROR(B14/(Assumptions!$B$4+B13),0) -> 0 | C15: =IFERROR(C14/(Assumptions!$B$4+C13),0) -> 0 | D15: =IFERROR(D14/(Assumptions!$B$4+D13),0) -> 0 | E15: =IFERROR(E14/(Assumptions!$B$4+E13),0) -> 0 | F15: =IFERROR(F14/(Assumptions!$B$4+F13),0) -> 0.095302581 | G15: =IFERROR(G14/(Assumptions!$B$4+G13),0) -> 0.36162769 | H15: =IFERROR(H14/(Assumptions!$B$4+H13),0) -> 0.83845592 | I15: =IFERROR(I14/(Assumptions!$B$4+I13),0) -> 1 | ... T15: =IFERROR(T14/(Assumptions!$B$4+T13),0) -> 1

Sheet Monthly Cash Flow
A1: ExitBlueprint — Monthly Cash Flow (Bootstrap, Mo 0-18)
A2: Line Item | B2: Mo 0 | C2: Mo 1 * | D2: Mo 2 | E2: Mo 3 | F2: Mo 4 | G2: Mo 5 | H2: Mo 6 | I2: Mo 7 | J2: Mo 8 | K2: Mo 9 | L2: Mo 10 | M2: Mo 11 | N2: Mo 12 | O2: Mo 13 | P2: Mo 14 | Q2: Mo 15 | R2: Mo 16 | S2: Mo 17 | T2: Mo 18
A3: Calendar | B3: Aug-26 | C3: Sep-26 | D3: Oct-26 | E3: Nov-26 | F3: Dec-26 | G3: Jan-27 | H3: Feb-27 | I3: Mar-27 | J3: Apr-27 | K3: May-27 | L3: Jun-27 | M3: Jul-27 | N3: Aug-27 | O3: Sep-27 | P3: Oct-27 | Q3: Nov-27 | R3: Dec-27 | S3: Jan-28 | T3: Feb-28
A4: CAPITAL INFLOWS
A5: Joe Bootstrap Loan — Drawdown | B5: =IF(0=Assumptions!$B$6,Assumptions!$B$4,0) -> 55000 | C5: =IF(1=Assumptions!$B$6,Assumptions!$B$4,0) -> 0 | D5: =IF(2=Assumptions!$B$6,Assumptions!$B$4,0) -> 0 | E5: =IF(3=Assumptions!$B$6,Assumptions!$B$4,0) -> 0 | F5: =IF(4=Assumptions!$B$6,Assumptions!$B$4,0) -> 0 | G5: =IF(5=Assumptions!$B$6,Assumptions!$B$4,0) -> 0 | H5: =IF(6=Assumptions!$B$6,Assumptions!$B$4,0) -> 0 | I5: =IF(7=Assumptions!$B$6,Assumptions!$B$4,0) -> 0 | J5: =IF(8=Assumptions!$B$6,Assumptions!$B$4,0) -> 0 | K5: =IF(9=Assumptions!$B$6,Assumptions!$B$4,0) -> 0 | L5: =IF(10=Assumptions!$B$6,Assumptions!$B$4,0) -> 0 | M5: =IF(11=Assumptions!$B$6,Assumptions!$B$4,0) -> 0 | N5: =IF(12=Assumptions!$B$6,Assumptions!$B$4,0) -> 0 | O5: =IF(13=Assumptions!$B$6,Assumptions!$B$4,0) -> 0 | P5: =IF(14=Assumptions!$B$6,Assumptions!$B$4,0) -> 0 | Q5: =IF(15=Assumptions!$B$6,Assumptions!$B$4,0) -> 0 | R5: =IF(16=Assumptions!$B$6,Assumptions!$B$4,0) -> 0 | S5: =IF(17=Assumptions!$B$6,Assumptions!$B$4,0) -> 0 | T5: =IF(18=Assumptions!$B$6,Assumptions!$B$4,0) -> 0 | U5: Funded once, Mo 0
A6: TOTAL CAPITAL INFLOWS | B6: =B5 -> 55000 | C6: =C5 -> 0 | D6: =D5 -> 0 | E6: =E5 -> 0 | F6: =F5 -> 0 | G6: =G5 -> 0 | H6: =H5 -> 0 | I6: =I5 -> 0 | ... T6: =T5 -> 0
A8: REVENUE & ADVISOR COUNTS
A9: Founding Advisors (count) | B9: =0 -> 0 | C9: =Assumptions!$B$56 -> 10 | D9: =C9+Assumptions!$B$57 -> 20 | E9: =D9 -> 20 | F9: =E9 -> 20 | G9: =F9 -> 20 | H9: =G9 -> 20 | I9: =H9 -> 20 | J9: =I9 -> 20 | K9: =J9 -> 20 | L9: =K9 -> 20 | ... T9: =S9 -> 20
A10: Standard — New Adds | B10: =0 -> 0 | C10: =0 -> 0 | D10: =0 -> 0 | E10: =Assumptions!$B$59 -> 10 | F10: =Assumptions!$B$60 -> 17 | G10: =Assumptions!$B$61 -> 24 | H10: =Assumptions!$B$62 -> 30 | I10: =Assumptions!$B$63 -> 37 | J10: =Assumptions!$B$64 -> 44 | K10: =Assumptions!$B$65 -> 51 | L10: =Assumptions!$B$66 -> 58 | M10: =Assumptions!$B$67 -> 64 | N10: =Assumptions!$B$68 -> 71 | O10: =Assumptions!$B$69 -> 78 | P10: =Assumptions!$B$70 -> 85 | Q10: =Assumptions!$B$71 -> 91 | R10: =Assumptions!$B$72 -> 98 | S10: =Assumptions!$B$73 -> 105 | T10: =Assumptions!$B$74 -> 112
A11: Standard — Churned (lost) | B11: =0 -> 0 | C11: =0 -> 0 | D11: =0 -> 0 | E11: =0 -> 0 | F11: =ROUND(E12*Assumptions!$B$77,0) -> 0 | G11: =ROUND(F12*Assumptions!$B$77,0) -> 0 | H11: =ROUND(G12*Assumptions!$B$77,0) -> 1 | I11: =ROUND(H12*Assumptions!$B$77,0) -> 1 | J11: =ROUND(I12*Assumptions!$B$77,0) -> 2 | K11: =ROUND(J12*Assumptions!$B$77,0) -> 2 | L11: =ROUND(K12*Assumptions!$B$77,0) -> 3 | M11: =ROUND(L12*Assumptions!$B$77,0) -> 4 | ... T11: =ROUND(S12*Assumptions!$B$77,0) -> 12
A12: Standard Advisors (count) | B12: =0 -> 0 | C12: =0 -> 0 | D12: =0 -> 0 | E12: =E10 -> 10 | F12: =E12+F10-F11 -> 27 | G12: =F12+G10-G11 -> 51 | H12: =G12+H10-H11 -> 80 | I12: =H12+I10-I11 -> 116 | J12: =I12+J10-J11 -> 158 | K12: =J12+K10-K11 -> 207 | L12: =K12+L10-L11 -> 262 | M12: =L12+M10-M11 -> 322 | ... T12: =S12+T10-T11 -> 904
A13: Total Advisors | B13: =B9+B12 -> 0 | C13: =C9+C12 -> 10 | D13: =D9+D12 -> 20 | E13: =E9+E12 -> 30 | F13: =F9+F12 -> 47 | G13: =G9+G12 -> 71 | H13: =H9+H12 -> 100 | I13: =I9+I12 -> 136 | ... T13: =T9+T12 -> 924
A14: Revenue — Founding | B14: =B9*Assumptions!$B$54 -> 0 | C14: =C9*Assumptions!$B$54 -> 1990 | D14: =D9*Assumptions!$B$54 -> 3980 | E14: =E9*Assumptions!$B$54 -> 3980 | F14: =F9*Assumptions!$B$54 -> 3980 | G14: =G9*Assumptions!$B$54 -> 3980 | H14: =H9*Assumptions!$B$54 -> 3980 | I14: =I9*Assumptions!$B$54 -> 3980 | ... T14: =T9*Assumptions!$B$54 -> 3980
A15: Revenue — Standard | B15: =B12*Assumptions!$B$55 -> 0 | C15: =C12*Assumptions!$B$55 -> 0 | D15: =D12*Assumptions!$B$55 -> 0 | E15: =E12*Assumptions!$B$55 -> 4990 | F15: =F12*Assumptions!$B$55 -> 13473 | G15: =G12*Assumptions!$B$55 -> 25449 | H15: =H12*Assumptions!$B$55 -> 39920 | I15: =I12*Assumptions!$B$55 -> 57884 | ... T15: =T12*Assumptions!$B$55 -> 451096
A16: TOTAL MRR | B16: =B14+B15 -> 0 | C16: =C14+C15 -> 1990 | D16: =D14+D15 -> 3980 | E16: =E14+E15 -> 8970 | F16: =F14+F15 -> 17453 | G16: =G14+G15 -> 29429 | H16: =H14+H15 -> 43900 | I16: =I14+I15 -> 61864 | ... T16: =T14+T15 -> 455076
A18: COST OF REVENUE
A19: Payment Processing | B19: =ROUND(B16*Assumptions!$B$51,0) -> 0 | C19: =ROUND(C16*Assumptions!$B$51,0) -> 58 | D19: =ROUND(D16*Assumptions!$B$51,0) -> 115 | E19: =ROUND(E16*Assumptions!$B$51,0) -> 260 | F19: =ROUND(F16*Assumptions!$B$51,0) -> 506 | G19: =ROUND(G16*Assumptions!$B$51,0) -> 853 | H19: =ROUND(H16*Assumptions!$B$51,0) -> 1273 | I19: =ROUND(I16*Assumptions!$B$51,0) -> 1794 | ... T19: =ROUND(T16*Assumptions!$B$51,0) -> 13197
A20: TOTAL COGS | B20: =B19 -> 0 | C20: =C19 -> 58 | D20: =D19 -> 115 | E20: =E19 -> 260 | F20: =F19 -> 506 | G20: =G19 -> 853 | H20: =H19 -> 1273 | I20: =I19 -> 1794 | ... T20: =T19 -> 13197
A22: GROSS PROFIT
A23: Gross Profit | B23: =B16-B20 -> 0 | C23: =C16-C20 -> 1932 | D23: =D16-D20 -> 3865 | E23: =E16-E20 -> 8710 | F23: =F16-F20 -> 16947 | G23: =G16-G20 -> 28576 | H23: =H16-H20 -> 42627 | I23: =I16-I20 -> 60070 | ... T23: =T16-T20 -> 441879
A24: Gross Margin % | B24: =IFERROR(B23/B16,0) -> 0 | C24: =IFERROR(C23/C16,0) -> 0.97085427 | D24: =IFERROR(D23/D16,0) -> 0.97110553 | E24: =IFERROR(E23/E16,0) -> 0.97101449 | F24: =IFERROR(F23/F16,0) -> 0.97100785 | G24: =IFERROR(G23/G16,0) -> 0.97101499 | H24: =IFERROR(H23/H16,0) -> 0.97100228 | I24: =IFERROR(I23/I16,0) -> 0.97100091 | ... T24: =IFERROR(T23/T16,0) -> 0.97100045
A26: FIXED OPERATING EXPENSES (cash)
A27: Founder Draw — Matthew (gated) | B27: =IF(B23>=Assumptions!$B$11,Assumptions!$B$11,0) -> 0 | C27: =IF(OR(B27>0,C23>=Assumptions!$B$11),Assumptions!$B$11,0) -> 0 | D27: =IF(OR(C27>0,D23>=Assumptions!$B$11),Assumptions!$B$11,0) -> 0 | E27: =IF(OR(D27>0,E23>=Assumptions!$B$11),Assumptions!$B$11,0) -> 5000 | F27: =IF(OR(E27>0,F23>=Assumptions!$B$11),Assumptions!$B$11,0) -> 5000 | G27: =IF(OR(F27>0,G23>=Assumptions!$B$11),Assumptions!$B$11,0) -> 5000 | H27: =IF(OR(G27>0,H23>=Assumptions!$B$11),Assumptions!$B$11,0) -> 5000 | I27: =IF(OR(H27>0,I23>=Assumptions!$B$11),Assumptions!$B$11,0) -> 5000 | J27: =IF(OR(I27>0,J23>=Assumptions!$B$11),Assumptions!$B$11,0) -> 5000 | ... T27: =IF(OR(S27>0,T23>=Assumptions!$B$11),Assumptions!$B$11,0) -> 5000 | U27: Off until gross profit >= target
A28: Bloom Growth (EOS) | B28: =Assumptions!$B$24 -> 299 | C28: =Assumptions!$B$24 -> 299 | D28: =Assumptions!$B$24 -> 299 | E28: =Assumptions!$B$24 -> 299 | F28: =Assumptions!$B$24 -> 299 | G28: =Assumptions!$B$24 -> 299 | H28: =Assumptions!$B$24 -> 299 | I28: =Assumptions!$B$24 -> 299 | ... T28: =Assumptions!$B$24 -> 299
A29: SOC 2 Platform (monthly) | B29: =Assumptions!$B$25 -> 1667 | C29: =Assumptions!$B$25 -> 1667 | D29: =Assumptions!$B$25 -> 1667 | E29: =Assumptions!$B$25 -> 1667 | F29: =Assumptions!$B$25 -> 1667 | G29: =Assumptions!$B$25 -> 1667 | H29: =Assumptions!$B$25 -> 1667 | I29: =Assumptions!$B$25 -> 1667 | ... T29: =Assumptions!$B$25 -> 1667
A30: TOTAL FIXED OPEX (cash) | B30: =B27+B28+B29 -> 1966 | C30: =C27+C28+C29 -> 1966 | D30: =D27+D28+D29 -> 1966 | E30: =E27+E28+E29 -> 6966 | F30: =F27+F28+F29 -> 6966 | G30: =G27+G28+G29 -> 6966 | H30: =H27+H28+H29 -> 6966 | I30: =I27+I28+I29 -> 6966 | ... T30: =T27+T28+T29 -> 6966
A32: SCALE-DRIVEN / VARIABLE OPEX
A33: Hosting / Infrastructure (tiered) | B33: =IF(B13<=50,Assumptions!$B$29,IF(B13<=150,Assumptions!$B$30,IF(B13<=500,Assumptions!$B$31,Assumptions!$B$32))) -> 500 | C33: =IF(C13<=50,Assumptions!$B$29,IF(C13<=150,Assumptions!$B$30,IF(C13<=500,Assumptions!$B$31,Assumptions!$B$32))) -> 500 | D33: =IF(D13<=50,Assumptions!$B$29,IF(D13<=150,Assumptions!$B$30,IF(D13<=500,Assumptions!$B$31,Assumptions!$B$32))) -> 500 | E33: =IF(E13<=50,Assumptions!$B$29,IF(E13<=150,Assumptions!$B$30,IF(E13<=500,Assumptions!$B$31,Assumptions!$B$32))) -> 500 | F33: =IF(F13<=50,Assumptions!$B$29,IF(F13<=150,Assumptions!$B$30,IF(F13<=500,Assumptions!$B$31,Assumptions!$B$32))) -> 500 | G33: =IF(G13<=50,Assumptions!$B$29,IF(G13<=150,Assumptions!$B$30,IF(G13<=500,Assumptions!$B$31,Assumptions!$B$32))) -> 1500 | H33: =IF(H13<=50,Assumptions!$B$29,IF(H13<=150,Assumptions!$B$30,IF(H13<=500,Assumptions!$B$31,Assumptions!$B$32))) -> 1500 | I33: =IF(I13<=50,Assumptions!$B$29,IF(I13<=150,Assumptions!$B$30,IF(I13<=500,Assumptions!$B$31,Assumptions!$B$32))) -> 1500 | ... T33: =IF(T13<=50,Assumptions!$B$29,IF(T13<=150,Assumptions!$B$30,IF(T13<=500,Assumptions!$B$31,Assumptions!$B$32))) -> 8000
A34: Contractor / Intern Pool (tiered) | B34: =IF(B13<=25,Assumptions!$B$34,IF(B13<=100,Assumptions!$B$35,IF(B13<=300,Assumptions!$B$36,Assumptions!$B$37))) -> 0 | C34: =IF(C13<=25,Assumptions!$B$34,IF(C13<=100,Assumptions!$B$35,IF(C13<=300,Assumptions!$B$36,Assumptions!$B$37))) -> 0 | D34: =IF(D13<=25,Assumptions!$B$34,IF(D13<=100,Assumptions!$B$35,IF(D13<=300,Assumptions!$B$36,Assumptions!$B$37))) -> 0 | E34: =IF(E13<=25,Assumptions!$B$34,IF(E13<=100,Assumptions!$B$35,IF(E13<=300,Assumptions!$B$36,Assumptions!$B$37))) -> 1500 | F34: =IF(F13<=25,Assumptions!$B$34,IF(F13<=100,Assumptions!$B$35,IF(F13<=300,Assumptions!$B$36,Assumptions!$B$37))) -> 1500 | G34: =IF(G13<=25,Assumptions!$B$34,IF(G13<=100,Assumptions!$B$35,IF(G13<=300,Assumptions!$B$36,Assumptions!$B$37))) -> 1500 | H34: =IF(H13<=25,Assumptions!$B$34,IF(H13<=100,Assumptions!$B$35,IF(H13<=300,Assumptions!$B$36,Assumptions!$B$37))) -> 1500 | I34: =IF(I13<=25,Assumptions!$B$34,IF(I13<=100,Assumptions!$B$35,IF(I13<=300,Assumptions!$B$36,Assumptions!$B$37))) -> 3500 | ... T34: =IF(T13<=25,Assumptions!$B$34,IF(T13<=100,Assumptions!$B$35,IF(T13<=300,Assumptions!$B$36,Assumptions!$B$37))) -> 6000
A35: Customer Success & Support (tiered) | B35: =IF(0<6,Assumptions!$B$39,IF(0<12,Assumptions!$B$40,Assumptions!$B$41)) -> 0 | C35: =IF(1<6,Assumptions!$B$39,IF(1<12,Assumptions!$B$40,Assumptions!$B$41)) -> 0 | D35: =IF(2<6,Assumptions!$B$39,IF(2<12,Assumptions!$B$40,Assumptions!$B$41)) -> 0 | E35: =IF(3<6,Assumptions!$B$39,IF(3<12,Assumptions!$B$40,Assumptions!$B$41)) -> 0 | F35: =IF(4<6,Assumptions!$B$39,IF(4<12,Assumptions!$B$40,Assumptions!$B$41)) -> 0 | G35: =IF(5<6,Assumptions!$B$39,IF(5<12,Assumptions!$B$40,Assumptions!$B$41)) -> 0 | H35: =IF(6<6,Assumptions!$B$39,IF(6<12,Assumptions!$B$40,Assumptions!$B$41)) -> 1500 | I35: =IF(7<6,Assumptions!$B$39,IF(7<12,Assumptions!$B$40,Assumptions!$B$41)) -> 1500 | J35: =IF(8<6,Assumptions!$B$39,IF(8<12,Assumptions!$B$40,Assumptions!$B$41)) -> 1500 | K35: =IF(9<6,Assumptions!$B$39,IF(9<12,Assumptions!$B$40,Assumptions!$B$41)) -> 1500 | L35: =IF(10<6,Assumptions!$B$39,IF(10<12,Assumptions!$B$40,Assumptions!$B$41)) -> 1500 | M35: =IF(11<6,Assumptions!$B$39,IF(11<12,Assumptions!$B$40,Assumptions!$B$41)) -> 1500 | N35: =IF(12<6,Assumptions!$B$39,IF(12<12,Assumptions!$B$40,Assumptions!$B$41)) -> 3500 | O35: =IF(13<6,Assumptions!$B$39,IF(13<12,Assumptions!$B$40,Assumptions!$B$41)) -> 3500 | P35: =IF(14<6,Assumptions!$B$39,IF(14<12,Assumptions!$B$40,Assumptions!$B$41)) -> 3500 | Q35: =IF(15<6,Assumptions!$B$39,IF(15<12,Assumptions!$B$40,Assumptions!$B$41)) -> 3500 | R35: =IF(16<6,Assumptions!$B$39,IF(16<12,Assumptions!$B$40,Assumptions!$B$41)) -> 3500 | S35: =IF(17<6,Assumptions!$B$39,IF(17<12,Assumptions!$B$40,Assumptions!$B$41)) -> 3500 | T35: =IF(18<6,Assumptions!$B$39,IF(18<12,Assumptions!$B$40,Assumptions!$B$41)) -> 3500
A36: Tools / SaaS Stack (tiered) | B36: =IF(0<6,Assumptions!$B$43,Assumptions!$B$44) -> 500 | C36: =IF(1<6,Assumptions!$B$43,Assumptions!$B$44) -> 500 | D36: =IF(2<6,Assumptions!$B$43,Assumptions!$B$44) -> 500 | E36: =IF(3<6,Assumptions!$B$43,Assumptions!$B$44) -> 500 | F36: =IF(4<6,Assumptions!$B$43,Assumptions!$B$44) -> 500 | G36: =IF(5<6,Assumptions!$B$43,Assumptions!$B$44) -> 500 | H36: =IF(6<6,Assumptions!$B$43,Assumptions!$B$44) -> 1000 | I36: =IF(7<6,Assumptions!$B$43,Assumptions!$B$44) -> 1000 | J36: =IF(8<6,Assumptions!$B$43,Assumptions!$B$44) -> 1000 | K36: =IF(9<6,Assumptions!$B$43,Assumptions!$B$44) -> 1000 | L36: =IF(10<6,Assumptions!$B$43,Assumptions!$B$44) -> 1000 | M36: =IF(11<6,Assumptions!$B$43,Assumptions!$B$44) -> 1000 | N36: =IF(12<6,Assumptions!$B$43,Assumptions!$B$44) -> 1000 | O36: =IF(13<6,Assumptions!$B$43,Assumptions!$B$44) -> 1000 | P36: =IF(14<6,Assumptions!$B$43,Assumptions!$B$44) -> 1000 | Q36: =IF(15<6,Assumptions!$B$43,Assumptions!$B$44) -> 1000 | R36: =IF(16<6,Assumptions!$B$43,Assumptions!$B$44) -> 1000 | S36: =IF(17<6,Assumptions!$B$43,Assumptions!$B$44) -> 1000 | T36: =IF(18<6,Assumptions!$B$43,Assumptions!$B$44) -> 1000
A37: Marketing Spend (ramp) | B37: =IF(0<=1,Assumptions!$B$46,IF(0=2,Assumptions!$B$47,IF(0=3,Assumptions!$B$48,Assumptions!$B$49))) -> 750 | C37: =IF(1<=1,Assumptions!$B$46,IF(1=2,Assumptions!$B$47,IF(1=3,Assumptions!$B$48,Assumptions!$B$49))) -> 750 | D37: =IF(2<=1,Assumptions!$B$46,IF(2=2,Assumptions!$B$47,IF(2=3,Assumptions!$B$48,Assumptions!$B$49))) -> 1500 | E37: =IF(3<=1,Assumptions!$B$46,IF(3=2,Assumptions!$B$47,IF(3=3,Assumptions!$B$48,Assumptions!$B$49))) -> 2250 | F37: =IF(4<=1,Assumptions!$B$46,IF(4=2,Assumptions!$B$47,IF(4=3,Assumptions!$B$48,Assumptions!$B$49))) -> 3000 | G37: =IF(5<=1,Assumptions!$B$46,IF(5=2,Assumptions!$B$47,IF(5=3,Assumptions!$B$48,Assumptions!$B$49))) -> 3000 | H37: =IF(6<=1,Assumptions!$B$46,IF(6=2,Assumptions!$B$47,IF(6=3,Assumptions!$B$48,Assumptions!$B$49))) -> 3000 | I37: =IF(7<=1,Assumptions!$B$46,IF(7=2,Assumptions!$B$47,IF(7=3,Assumptions!$B$48,Assumptions!$B$49))) -> 3000 | J37: =IF(8<=1,Assumptions!$B$46,IF(8=2,Assumptions!$B$47,IF(8=3,Assumptions!$B$48,Assumptions!$B$49))) -> 3000 | K37: =IF(9<=1,Assumptions!$B$46,IF(9=2,Assumptions!$B$47,IF(9=3,Assumptions!$B$48,Assumptions!$B$49))) -> 3000 | L37: =IF(10<=1,Assumptions!$B$46,IF(10=2,Assumptions!$B$47,IF(10=3,Assumptions!$B$48,Assumptions!$B$49))) -> 3000 | M37: =IF(11<=1,Assumptions!$B$46,IF(11=2,Assumptions!$B$47,IF(11=3,Assumptions!$B$48,Assumptions!$B$49))) -> 3000 | N37: =IF(12<=1,Assumptions!$B$46,IF(12=2,Assumptions!$B$47,IF(12=3,Assumptions!$B$48,Assumptions!$B$49))) -> 3000 | O37: =IF(13<=1,Assumptions!$B$46,IF(13=2,Assumptions!$B$47,IF(13=3,Assumptions!$B$48,Assumptions!$B$49))) -> 3000 | P37: =IF(14<=1,Assumptions!$B$46,IF(14=2,Assumptions!$B$47,IF(14=3,Assumptions!$B$48,Assumptions!$B$49))) -> 3000 | Q37: =IF(15<=1,Assumptions!$B$46,IF(15=2,Assumptions!$B$47,IF(15=3,Assumptions!$B$48,Assumptions!$B$49))) -> 3000 | R37: =IF(16<=1,Assumptions!$B$46,IF(16=2,Assumptions!$B$47,IF(16=3,Assumptions!$B$48,Assumptions!$B$49))) -> 3000 | S37: =IF(17<=1,Assumptions!$B$46,IF(17=2,Assumptions!$B$47,IF(17=3,Assumptions!$B$48,Assumptions!$B$49))) -> 3000 | T37: =IF(18<=1,Assumptions!$B$46,IF(18=2,Assumptions!$B$47,IF(18=3,Assumptions!$B$48,Assumptions!$B$49))) -> 3000
A38: TOTAL VARIABLE OPEX | B38: =SUM(B33:B37) -> 1750 | C38: =SUM(C33:C37) -> 1750 | D38: =SUM(D33:D37) -> 2500 | E38: =SUM(E33:E37) -> 4750 | F38: =SUM(F33:F37) -> 5500 | G38: =SUM(G33:G37) -> 6500 | H38: =SUM(H33:H37) -> 8500 | I38: =SUM(I33:I37) -> 10500 | ... T38: =SUM(T33:T37) -> 21500
A40: ONE-TIME / NON-RECURRING (cash)
A41: Legal — Entity Formation | B41: =IF(0=0,Assumptions!$B$16,0) -> 1500 | C41: =IF(1=0,Assumptions!$B$16,0) -> 0 | D41: =IF(2=0,Assumptions!$B$16,0) -> 0 | E41: =IF(3=0,Assumptions!$B$16,0) -> 0 | F41: =IF(4=0,Assumptions!$B$16,0) -> 0 | G41: =IF(5=0,Assumptions!$B$16,0) -> 0 | H41: =IF(6=0,Assumptions!$B$16,0) -> 0 | I41: =IF(7=0,Assumptions!$B$16,0) -> 0 | J41: =IF(8=0,Assumptions!$B$16,0) -> 0 | K41: =IF(9=0,Assumptions!$B$16,0) -> 0 | L41: =IF(10=0,Assumptions!$B$16,0) -> 0 | M41: =IF(11=0,Assumptions!$B$16,0) -> 0 | N41: =IF(12=0,Assumptions!$B$16,0) -> 0 | O41: =IF(13=0,Assumptions!$B$16,0) -> 0 | P41: =IF(14=0,Assumptions!$B$16,0) -> 0 | Q41: =IF(15=0,Assumptions!$B$16,0) -> 0 | R41: =IF(16=0,Assumptions!$B$16,0) -> 0 | S41: =IF(17=0,Assumptions!$B$16,0) -> 0 | T41: =IF(18=0,Assumptions!$B$16,0) -> 0
A42: Legal — Operating Agreement | B42: =IF(0=0,Assumptions!$B$17,0) -> 3000 | C42: =IF(1=0,Assumptions!$B$17,0) -> 0 | D42: =IF(2=0,Assumptions!$B$17,0) -> 0 | E42: =IF(3=0,Assumptions!$B$17,0) -> 0 | F42: =IF(4=0,Assumptions!$B$17,0) -> 0 | G42: =IF(5=0,Assumptions!$B$17,0) -> 0 | H42: =IF(6=0,Assumptions!$B$17,0) -> 0 | I42: =IF(7=0,Assumptions!$B$17,0) -> 0 | J42: =IF(8=0,Assumptions!$B$17,0) -> 0 | K42: =IF(9=0,Assumptions!$B$17,0) -> 0 | L42: =IF(10=0,Assumptions!$B$17,0) -> 0 | M42: =IF(11=0,Assumptions!$B$17,0) -> 0 | N42: =IF(12=0,Assumptions!$B$17,0) -> 0 | O42: =IF(13=0,Assumptions!$B$17,0) -> 0 | P42: =IF(14=0,Assumptions!$B$17,0) -> 0 | Q42: =IF(15=0,Assumptions!$B$17,0) -> 0 | R42: =IF(16=0,Assumptions!$B$17,0) -> 0 | S42: =IF(17=0,Assumptions!$B$17,0) -> 0 | T42: =IF(18=0,Assumptions!$B$17,0) -> 0
A43: Legal — Trademark / IP | B43: =IF(0=0,Assumptions!$B$18,0) -> 3500 | C43: =IF(1=0,Assumptions!$B$18,0) -> 0 | D43: =IF(2=0,Assumptions!$B$18,0) -> 0 | E43: =IF(3=0,Assumptions!$B$18,0) -> 0 | F43: =IF(4=0,Assumptions!$B$18,0) -> 0 | G43: =IF(5=0,Assumptions!$B$18,0) -> 0 | H43: =IF(6=0,Assumptions!$B$18,0) -> 0 | I43: =IF(7=0,Assumptions!$B$18,0) -> 0 | J43: =IF(8=0,Assumptions!$B$18,0) -> 0 | K43: =IF(9=0,Assumptions!$B$18,0) -> 0 | L43: =IF(10=0,Assumptions!$B$18,0) -> 0 | M43: =IF(11=0,Assumptions!$B$18,0) -> 0 | N43: =IF(12=0,Assumptions!$B$18,0) -> 0 | O43: =IF(13=0,Assumptions!$B$18,0) -> 0 | P43: =IF(14=0,Assumptions!$B$18,0) -> 0 | Q43: =IF(15=0,Assumptions!$B$18,0) -> 0 | R43: =IF(16=0,Assumptions!$B$18,0) -> 0 | S43: =IF(17=0,Assumptions!$B$18,0) -> 0 | T43: =IF(18=0,Assumptions!$B$18,0) -> 0
A44: Legal — ToS / Privacy Policy | B44: =IF(0=0,Assumptions!$B$19,0) -> 2000 | C44: =IF(1=0,Assumptions!$B$19,0) -> 0 | D44: =IF(2=0,Assumptions!$B$19,0) -> 0 | E44: =IF(3=0,Assumptions!$B$19,0) -> 0 | F44: =IF(4=0,Assumptions!$B$19,0) -> 0 | G44: =IF(5=0,Assumptions!$B$19,0) -> 0 | H44: =IF(6=0,Assumptions!$B$19,0) -> 0 | I44: =IF(7=0,Assumptions!$B$19,0) -> 0 | J44: =IF(8=0,Assumptions!$B$19,0) -> 0 | K44: =IF(9=0,Assumptions!$B$19,0) -> 0 | L44: =IF(10=0,Assumptions!$B$19,0) -> 0 | M44: =IF(11=0,Assumptions!$B$19,0) -> 0 | N44: =IF(12=0,Assumptions!$B$19,0) -> 0 | O44: =IF(13=0,Assumptions!$B$19,0) -> 0 | P44: =IF(14=0,Assumptions!$B$19,0) -> 0 | Q44: =IF(15=0,Assumptions!$B$19,0) -> 0 | R44: =IF(16=0,Assumptions!$B$19,0) -> 0 | S44: =IF(17=0,Assumptions!$B$19,0) -> 0 | T44: =IF(18=0,Assumptions!$B$19,0) -> 0
A45: SOC 2 Setup (spread) | B45: =IF(0<Assumptions!$B$21,Assumptions!$B$20/Assumptions!$B$21,0) -> 6666.6667 | C45: =IF(1<Assumptions!$B$21,Assumptions!$B$20/Assumptions!$B$21,0) -> 6666.6667 | D45: =IF(2<Assumptions!$B$21,Assumptions!$B$20/Assumptions!$B$21,0) -> 6666.6667 | E45: =IF(3<Assumptions!$B$21,Assumptions!$B$20/Assumptions!$B$21,0) -> 0 | F45: =IF(4<Assumptions!$B$21,Assumptions!$B$20/Assumptions!$B$21,0) -> 0 | G45: =IF(5<Assumptions!$B$21,Assumptions!$B$20/Assumptions!$B$21,0) -> 0 | H45: =IF(6<Assumptions!$B$21,Assumptions!$B$20/Assumptions!$B$21,0) -> 0 | I45: =IF(7<Assumptions!$B$21,Assumptions!$B$20/Assumptions!$B$21,0) -> 0 | J45: =IF(8<Assumptions!$B$21,Assumptions!$B$20/Assumptions!$B$21,0) -> 0 | K45: =IF(9<Assumptions!$B$21,Assumptions!$B$20/Assumptions!$B$21,0) -> 0 | L45: =IF(10<Assumptions!$B$21,Assumptions!$B$20/Assumptions!$B$21,0) -> 0 | M45: =IF(11<Assumptions!$B$21,Assumptions!$B$20/Assumptions!$B$21,0) -> 0 | N45: =IF(12<Assumptions!$B$21,Assumptions!$B$20/Assumptions!$B$21,0) -> 0 | O45: =IF(13<Assumptions!$B$21,Assumptions!$B$20/Assumptions!$B$21,0) -> 0 | P45: =IF(14<Assumptions!$B$21,Assumptions!$B$20/Assumptions!$B$21,0) -> 0 | Q45: =IF(15<Assumptions!$B$21,Assumptions!$B$20/Assumptions!$B$21,0) -> 0 | R45: =IF(16<Assumptions!$B$21,Assumptions!$B$20/Assumptions!$B$21,0) -> 0 | S45: =IF(17<Assumptions!$B$21,Assumptions!$B$20/Assumptions!$B$21,0) -> 0 | T45: =IF(18<Assumptions!$B$21,Assumptions!$B$20/Assumptions!$B$21,0) -> 0
A46: TOTAL ONE-TIME COSTS | B46: =SUM(B41:B45) -> 16666.667 | C46: =SUM(C41:C45) -> 6666.6667 | D46: =SUM(D41:D45) -> 6666.6667 | E46: =SUM(E41:E45) -> 0 | F46: =SUM(F41:F45) -> 0 | G46: =SUM(G41:G45) -> 0 | H46: =SUM(H41:H45) -> 0 | I46: =SUM(I41:I45) -> 0 | ... T46: =SUM(T41:T45) -> 0
...

Sheet Dashboard
A1: ExitBlueprint — Bootstrap Dashboard
A2: One-screen read on the bootstrap: what Joe funds, when it's repaid, when the business self-funds.
A4: JOE'S BOOTSTRAP LOAN
A5: Loan principal (from Joe) | B5: =Assumptions!$B$4 -> 55000 | D5: Founder loan; no equity taken
A6: Annual interest rate | B6: =Assumptions!$B$5 -> 0.06
A7: Total interest accrued (life of loan) | B7: =SUM('Monthly Cash Flow'!B59:T59) -> 1870.5909 | D7: Interest accrues (PIK) until swept
A8: Total repaid to Joe by Mo 18 | B8: =SUM('Monthly Cash Flow'!B53:T53) -> 56870.591
A9: Loan fully repaid | B9: =COUNTIF('Monthly Cash Flow'!B60:T60,">0.5") -> 7 | C9: =INDEX('Monthly Cash Flow'!B3:T3,1,(COUNTIF('Monthly Cash Flow'!B60:T60,">0.5"))+1) -> Mar-27 | D9: First month balance hits zero
A10: CASH & RUNWAY
A11: Peak cumulative cash need (trough) | B11: =-MIN('Monthly Cash Flow'!B55:T55) -> 39107 | D11: Deepest operating hole; drives loan size
A12: Minimum ending cash (any month) | B12: =MIN('Monthly Cash Flow'!B54:T54) -> 15000 | D12: Stays at/above the buffer if solvent
A13: Cash buffer floor held | B13: =Assumptions!$B$7 -> 15000
A14: Ending cash at Mo 18 (Feb-28) | B14: ='Monthly Cash Flow'!T54 -> 2427121.4
A15: SELF-FUNDING MILESTONES
A16: Founder draws begin | B16: =COUNTIF('Monthly Cash Flow'!B27:T27,0) -> 3 | C16: =INDEX('Monthly Cash Flow'!B3:T3,1,(COUNTIF('Monthly Cash Flow'!B27:T27,0))+1) -> Nov-26 | D16: First month gross profit >= draw target
A17: Founder draw once started ($/mo) | B17: =Assumptions!$B$11 -> 5000
A18: Operating breakeven (cash-flow +) | B18: =COUNTIF('Monthly Cash Flow'!B50:T50,"<0") -> 4 | C18: =INDEX('Monthly Cash Flow'!B3:T3,1,(COUNTIF('Monthly Cash Flow'!B50:T50,"<0"))+1) -> Dec-26 | D18: First month net operating cash flow >= 0
A19: TRACTION AT MONTH 18 (Feb-28)
A20: Total advisors | B20: ='Monthly Cash Flow'!T13 -> 924
A21: MRR | B21: ='Monthly Cash Flow'!T16 -> 455076
A22: ARR (MRR x 12) | B22: ='Monthly Cash Flow'!T65 -> 5460912
A23: Cumulative revenue (Mo 0-18) | B23: ='Monthly Cash Flow'!T66 -> 2892992
A24: Operating EBITDA (Mo 18) | B24: ='Monthly Cash Flow'!T67 -> 413413

Sheet SaaS Metrics
A1: ExitBlueprint — SaaS Unit Economics
A2: Blended metrics at scale (Mo 18) and key ratios. Pulls from Assumptions + Monthly Cash Flow.
A4: PRICING & RETENTION
A5: Blended ARPU (MRR / advisor, Mo 18) | B5: ='Monthly Cash Flow'!T16/'Monthly Cash Flow'!T13 -> 492.50649 | D5: Mix of founding $199 + standard $499
A6: Gross margin % | B6: ='Monthly Cash Flow'!T24 -> 0.97100045 | D6: After payment processing
A7: Monthly logo churn | B7: =Assumptions!$B$77 -> 0.015
A8: Annualized churn | B8: =1-(1-Assumptions!$B$77)^12 -> 0.16586803
A9: Net revenue retention (monthly) | B9: =Assumptions!$B$78 -> 1.005
A10: ACQUISITION ECONOMICS
A11: Blended CAC | B11: =Assumptions!$B$79 -> 350
A12: Lifetime (months) = 1 / churn | B12: =1/Assumptions!$B$77 -> 66.666667 | D12: Avg advisor lifespan
A13: LTV = ARPU x GM% / churn | B13: =('Monthly Cash Flow'!T16/'Monthly Cash Flow'!T13)*'Monthly Cash Flow'!T24/Assumptions!$B$77 -> 31881.602
A14: LTV : CAC | B14: =(('Monthly Cash Flow'!T16/'Monthly Cash Flow'!T13)*'Monthly Cash Flow'!T24/Assumptions!$B$77)/Assumptions!$B$79 -> 91.090291 | D14: >3x is healthy
A15: CAC payback (months) = CAC / (ARPU x GM%) | B15: =Assumptions!$B$79/(('Monthly Cash Flow'!T16/'Monthly Cash Flow'!T13)*'Monthly Cash Flow'!T24) -> 0.73187456 | D15: <12 mo is strong
A16: GROWTH & EFFICIENCY
A17: MRR growth, Mo 17 -> Mo 18 | B17: ='Monthly Cash Flow'!T16/'Monthly Cash Flow'!S16-1 -> 0.12315636
A18: ARR at Mo 18 | B18: ='Monthly Cash Flow'!T65 -> 5460912
A19: Rule of 40 (MoM growth% + op margin%) | B19: =('Monthly Cash Flow'!T16/'Monthly Cash Flow'!S16-1)+('Monthly Cash Flow'!T67/'Monthly Cash Flow'!T16) -> 1.0316046 | D19: Monthly proxy; >3.3%/mo ~ 40%/yr

Sheet Downside (Slow GTM)
A1: ExitBlueprint — Downside: Slow GTM (ramp +2 mo, adds haircut)
A2: Same cost engine as base. Revenue ramp shifted +2 months and standard adds scaled by the haircut. No debt sweep here — we hold Joe's cash to see if it lasts.
A3: Line Item | B3: Mo 0 | C3: Mo 1 | D3: Mo 2 | E3: Mo 3 | F3: Mo 4 | G3: Mo 5 | H3: Mo 6 | I3: Mo 7 | J3: Mo 8 | K3: Mo 9 | L3: Mo 10 | M3: Mo 11 | N3: Mo 12 | O3: Mo 13 | P3: Mo 14 | Q3: Mo 15 | R3: Mo 16 | S3: Mo 17 | T3: Mo 18
A4: Calendar | B4: Aug-26 | C4: Sep-26 | D4: Oct-26 | E4: Nov-26 | F4: Dec-26 | G4: Jan-27 | H4: Feb-27 | I4: Mar-27 | J4: Apr-27 | K4: May-27 | L4: Jun-27 | M4: Jul-27 | N4: Aug-27 | O4: Sep-27 | P4: Oct-27 | Q4: Nov-27 | R4: Dec-27 | S4: Jan-28 | T4: Feb-28
A5: SCENARIO LEVER
A6: Standard-adds haircut (x base ramp) | B6: 0.6 | C6: Blue lever: 1.0 = base ramp; 0.6 = 40% slower adds
A7: GTM slip baked into formulas | B7: +2 months | C7: Founding & standard adds shifted 2 months later than base
A8: Founding Advisors (count) | B8: =0 -> 0 | C8: =0 -> 0 | D8: =0 -> 0 | E8: =Assumptions!$B$56 -> 10 | F8: =E8+Assumptions!$B$57 -> 20 | G8: =F8 -> 20 | H8: =G8 -> 20 | I8: =H8 -> 20 | J8: =I8 -> 20 | K8: =J8 -> 20 | L8: =K8 -> 20 | M8: =L8 -> 20 | N8: =M8 -> 20 | ... T8: =S8 -> 20
A9: Standard — New Adds (haircut) | B9: =0 -> 0 | C9: =0 -> 0 | D9: =0 -> 0 | E9: =0 -> 0 | F9: =0 -> 0 | G9: =ROUND(Assumptions!$B$59*$B$6,0) -> 6 | H9: =ROUND(Assumptions!$B$60*$B$6,0) -> 10 | I9: =ROUND(Assumptions!$B$61*$B$6,0) -> 14 | J9: =ROUND(Assumptions!$B$62*$B$6,0) -> 18 | K9: =ROUND(Assumptions!$B$63*$B$6,0) -> 22 | L9: =ROUND(Assumptions!$B$64*$B$6,0) -> 26 | M9: =ROUND(Assumptions!$B$65*$B$6,0) -> 31 | N9: =ROUND(Assumptions!$B$66*$B$6,0) -> 35 | O9: =ROUND(Assumptions!$B$67*$B$6,0) -> 38 | P9: =ROUND(Assumptions!$B$68*$B$6,0) -> 43 | Q9: =ROUND(Assumptions!$B$69*$B$6,0) -> 47 | R9: =ROUND(Assumptions!$B$70*$B$6,0) -> 51 | S9: =ROUND(Assumptions!$B$71*$B$6,0) -> 55 | T9: =ROUND(Assumptions!$B$72*$B$6,0) -> 59
A10: Standard — Churned | B10: =0 -> 0 | C10: =0 -> 0 | D10: =0 -> 0 | E10: =0 -> 0 | F10: =0 -> 0 | G10: =0 -> 0 | H10: =ROUND(G11*Assumptions!$B$77,0) -> 0 | I10: =ROUND(H11*Assumptions!$B$77,0) -> 0 | J10: =ROUND(I11*Assumptions!$B$77,0) -> 0 | K10: =ROUND(J11*Assumptions!$B$77,0) -> 1 | L10: =ROUND(K11*Assumptions!$B$77,0) -> 1 | M10: =ROUND(L11*Assumptions!$B$77,0) -> 1 | N10: =ROUND(M11*Assumptions!$B$77,0) -> 2 | O10: =ROUND(N11*Assumptions!$B$77,0) -> 2 | ... T10: =ROUND(S11*Assumptions!$B$77,0) -> 6
A11: Standard Advisors (count) | B11: =0 -> 0 | C11: =0 -> 0 | D11: =0 -> 0 | E11: =0 -> 0 | F11: =0 -> 0 | G11: =G9 -> 6 | H11: =G11+H9-H10 -> 16 | I11: =H11+I9-I10 -> 30 | J11: =I11+J9-J10 -> 48 | K11: =J11+K9-K10 -> 69 | L11: =K11+L9-L10 -> 94 | M11: =L11+M9-M10 -> 124 | N11: =M11+N9-N10 -> 157 | O11: =N11+O9-O10 -> 193 | ... T11: =S11+T9-T10 -> 427
A12: Total Advisors | B12: =B8+B11 -> 0 | C12: =C8+C11 -> 0 | D12: =D8+D11 -> 0 | E12: =E8+E11 -> 10 | F12: =F8+F11 -> 20 | G12: =G8+G11 -> 26 | H12: =H8+H11 -> 36 | I12: =I8+I11 -> 50 | ... T12: =T8+T11 -> 447
A13: TOTAL MRR | B13: =B8*Assumptions!$B$54+B11*Assumptions!$B$55 -> 0 | C13: =C8*Assumptions!$B$54+C11*Assumptions!$B$55 -> 0 | D13: =D8*Assumptions!$B$54+D11*Assumptions!$B$55 -> 0 | E13: =E8*Assumptions!$B$54+E11*Assumptions!$B$55 -> 1990 | F13: =F8*Assumptions!$B$54+F11*Assumptions!$B$55 -> 3980 | G13: =G8*Assumptions!$B$54+G11*Assumptions!$B$55 -> 6974 | H13: =H8*Assumptions!$B$54+H11*Assumptions!$B$55 -> 11964 | I13: =I8*Assumptions!$B$54+I11*Assumptions!$B$55 -> 18950 | ... T13: =T8*Assumptions!$B$54+T11*Assumptions!$B$55 -> 217053
A14: COSTS (same engine as base)
A15: Payment Processing | B15: =ROUND(B13*Assumptions!$B$51,0) -> 0 | C15: =ROUND(C13*Assumptions!$B$51,0) -> 0 | D15: =ROUND(D13*Assumptions!$B$51,0) -> 0 | E15: =ROUND(E13*Assumptions!$B$51,0) -> 58 | F15: =ROUND(F13*Assumptions!$B$51,0) -> 115 | G15: =ROUND(G13*Assumptions!$B$51,0) -> 202 | H15: =ROUND(H13*Assumptions!$B$51,0) -> 347 | I15: =ROUND(I13*Assumptions!$B$51,0) -> 550 | ... T15: =ROUND(T13*Assumptions!$B$51,0) -> 6295
A16: Gross Profit | B16: =B13-B15 -> 0 | C16: =C13-C15 -> 0 | D16: =D13-D15 -> 0 | E16: =E13-E15 -> 1932 | F16: =F13-F15 -> 3865 | G16: =G13-G15 -> 6772 | H16: =H13-H15 -> 11617 | I16: =I13-I15 -> 18400 | ... T16: =T13-T15 -> 210758
A17: Founder Draw (gated) | B17: =IF(B16>=Assumptions!$B$11,Assumptions!$B$11,0) -> 0 | C17: =IF(OR(B17>0,C16>=Assumptions!$B$11),Assumptions!$B$11,0) -> 0 | D17: =IF(OR(C17>0,D16>=Assumptions!$B$11),Assumptions!$B$11,0) -> 0 | E17: =IF(OR(D17>0,E16>=Assumptions!$B$11),Assumptions!$B$11,0) -> 0 | F17: =IF(OR(E17>0,F16>=Assumptions!$B$11),Assumptions!$B$11,0) -> 0 | G17: =IF(OR(F17>0,G16>=Assumptions!$B$11),Assumptions!$B$11,0) -> 5000 | H17: =IF(OR(G17>0,H16>=Assumptions!$B$11),Assumptions!$B$11,0) -> 5000 | I17: =IF(OR(H17>0,I16>=Assumptions!$B$11),Assumptions!$B$11,0) -> 5000 | J17: =IF(OR(I17>0,J16>=Assumptions!$B$11),Assumptions!$B$11,0) -> 5000 | ... T17: =IF(OR(S17>0,T16>=Assumptions!$B$11),Assumptions!$B$11,0) -> 5000
A18: Fixed Opex (draw+Bloom+SOC2) | B18: =B17+Assumptions!$B$24+Assumptions!$B$25 -> 1966 | C18: =C17+Assumptions!$B$24+Assumptions!$B$25 -> 1966 | D18: =D17+Assumptions!$B$24+Assumptions!$B$25 -> 1966 | E18: =E17+Assumptions!$B$24+Assumptions!$B$25 -> 1966 | F18: =F17+Assumptions!$B$24+Assumptions!$B$25 -> 1966 | G18: =G17+Assumptions!$B$24+Assumptions!$B$25 -> 6966 | H18: =H17+Assumptions!$B$24+Assumptions!$B$25 -> 6966 | I18: =I17+Assumptions!$B$24+Assumptions!$B$25 -> 6966 | ... T18: =T17+Assumptions!$B$24+Assumptions!$B$25 -> 6966
A19: Hosting (tiered) | B19: =IF(B12<=50,Assumptions!$B$29,IF(B12<=150,Assumptions!$B$30,IF(B12<=500,Assumptions!$B$31,Assumptions!$B$32))) -> 500 | C19: =IF(C12<=50,Assumptions!$B$29,IF(C12<=150,Assumptions!$B$30,IF(C12<=500,Assumptions!$B$31,Assumptions!$B$32))) -> 500 | D19: =IF(D12<=50,Assumptions!$B$29,IF(D12<=150,Assumptions!$B$30,IF(D12<=500,Assumptions!$B$31,Assumptions!$B$32))) -> 500 | E19: =IF(E12<=50,Assumptions!$B$29,IF(E12<=150,Assumptions!$B$30,IF(E12<=500,Assumptions!$B$31,Assumptions!$B$32))) -> 500 | F19: =IF(F12<=50,Assumptions!$B$29,IF(F12<=150,Assumptions!$B$30,IF(F12<=500,Assumptions!$B$31,Assumptions!$B$32))) -> 500 | G19: =IF(G12<=50,Assumptions!$B$29,IF(G12<=150,Assumptions!$B$30,IF(G12<=500,Assumptions!$B$31,Assumptions!$B$32))) -> 500 | H19: =IF(H12<=50,Assumptions!$B$29,IF(H12<=150,Assumptions!$B$30,IF(H12<=500,Assumptions!$B$31,Assumptions!$B$32))) -> 500 | I19: =IF(I12<=50,Assumptions!$B$29,IF(I12<=150,Assumptions!$B$30,IF(I12<=500,Assumptions!$B$31,Assumptions!$B$32))) -> 500 | ... T19: =IF(T12<=50,Assumptions!$B$29,IF(T12<=150,Assumptions!$B$30,IF(T12<=500,Assumptions!$B$31,Assumptions!$B$32))) -> 3000
A20: Contractor Pool (tiered) | B20: =IF(B12<=25,Assumptions!$B$34,IF(B12<=100,Assumptions!$B$35,IF(B12<=300,Assumptions!$B$36,Assumptions!$B$37))) -> 0 | C20: =IF(C12<=25,Assumptions!$B$34,IF(C12<=100,Assumptions!$B$35,IF(C12<=300,Assumptions!$B$36,Assumptions!$B$37))) -> 0 | D20: =IF(D12<=25,Assumptions!$B$34,IF(D12<=100,Assumptions!$B$35,IF(D12<=300,Assumptions!$B$36,Assumptions!$B$37))) -> 0 | E20: =IF(E12<=25,Assumptions!$B$34,IF(E12<=100,Assumptions!$B$35,IF(E12<=300,Assumptions!$B$36,Assumptions!$B$37))) -> 0 | F20: =IF(F12<=25,Assumptions!$B$34,IF(F12<=100,Assumptions!$B$35,IF(F12<=300,Assumptions!$B$36,Assumptions!$B$37))) -> 0 | G20: =IF(G12<=25,Assumptions!$B$34,IF(G12<=100,Assumptions!$B$35,IF(G12<=300,Assumptions!$B$36,Assumptions!$B$37))) -> 1500 | H20: =IF(H12<=25,Assumptions!$B$34,IF(H12<=100,Assumptions!$B$35,IF(H12<=300,Assumptions!$B$36,Assumptions!$B$37))) -> 1500 | I20: =IF(I12<=25,Assumptions!$B$34,IF(I12<=100,Assumptions!$B$35,IF(I12<=300,Assumptions!$B$36,Assumptions!$B$37))) -> 1500 | ... T20: =IF(T12<=25,Assumptions!$B$34,IF(T12<=100,Assumptions!$B$35,IF(T12<=300,Assumptions!$B$36,Assumptions!$B$37))) -> 6000
A21: CS & Support (tiered) | B21: =IF(0<6,Assumptions!$B$39,IF(0<12,Assumptions!$B$40,Assumptions!$B$41)) -> 0 | C21: =IF(1<6,Assumptions!$B$39,IF(1<12,Assumptions!$B$40,Assumptions!$B$41)) -> 0 | D21: =IF(2<6,Assumptions!$B$39,IF(2<12,Assumptions!$B$40,Assumptions!$B$41)) -> 0 | E21: =IF(3<6,Assumptions!$B$39,IF(3<12,Assumptions!$B$40,Assumptions!$B$41)) -> 0 | F21: =IF(4<6,Assumptions!$B$39,IF(4<12,Assumptions!$B$40,Assumptions!$B$41)) -> 0 | G21: =IF(5<6,Assumptions!$B$39,IF(5<12,Assumptions!$B$40,Assumptions!$B$41)) -> 0 | H21: =IF(6<6,Assumptions!$B$39,IF(6<12,Assumptions!$B$40,Assumptions!$B$41)) -> 1500 | I21: =IF(7<6,Assumptions!$B$39,IF(7<12,Assumptions!$B$40,Assumptions!$B$41)) -> 1500 | J21: =IF(8<6,Assumptions!$B$39,IF(8<12,Assumptions!$B$40,Assumptions!$B$41)) -> 1500 | K21: =IF(9<6,Assumptions!$B$39,IF(9<12,Assumptions!$B$40,Assumptions!$B$41)) -> 1500 | L21: =IF(10<6,Assumptions!$B$39,IF(10<12,Assumptions!$B$40,Assumptions!$B$41)) -> 1500 | M21: =IF(11<6,Assumptions!$B$39,IF(11<12,Assumptions!$B$40,Assumptions!$B$41)) -> 1500 | N21: =IF(12<6,Assumptions!$B$39,IF(12<12,Assumptions!$B$40,Assumptions!$B$41)) -> 3500 | O21: =IF(13<6,Assumptions!$B$39,IF(13<12,Assumptions!$B$40,Assumptions!$B$41)) -> 3500 | P21: =IF(14<6,Assumptions!$B$39,IF(14<12,Assumptions!$B$40,Assumptions!$B$41)) -> 3500 | Q21: =IF(15<6,Assumptions!$B$39,IF(15<12,Assumptions!$B$40,Assumptions!$B$41)) -> 3500 | R21: =IF(16<6,Assumptions!$B$39,IF(16<12,Assumptions!$B$40,Assumptions!$B$41)) -> 3500 | S21: =IF(17<6,Assumptions!$B$39,IF(17<12,Assumptions!$B$40,Assumptions!$B$41)) -> 3500 | T21: =IF(18<6,Assumptions!$B$39,IF(18<12,Assumptions!$B$40,Assumptions!$B$41)) -> 3500
A22: Tools (tiered) | B22: =IF(0<6,Assumptions!$B$43,Assumptions!$B$44) -> 500 | C22: =IF(1<6,Assumptions!$B$43,Assumptions!$B$44) -> 500 | D22: =IF(2<6,Assumptions!$B$43,Assumptions!$B$44) -> 500 | E22: =IF(3<6,Assumptions!$B$43,Assumptions!$B$44) -> 500 | F22: =IF(4<6,Assumptions!$B$43,Assumptions!$B$44) -> 500 | G22: =IF(5<6,Assumptions!$B$43,Assumptions!$B$44) -> 500 | H22: =IF(6<6,Assumptions!$B$43,Assumptions!$B$44) -> 1000 | I22: =IF(7<6,Assumptions!$B$43,Assumptions!$B$44) -> 1000 | J22: =IF(8<6,Assumptions!$B$43,Assumptions!$B$44) -> 1000 | K22: =IF(9<6,Assumptions!$B$43,Assumptions!$B$44) -> 1000 | L22: =IF(10<6,Assumptions!$B$43,Assumptions!$B$44) -> 1000 | M22: =IF(11<6,Assumptions!$B$43,Assumptions!$B$44) -> 1000 | N22: =IF(12<6,Assumptions!$B$43,Assumptions!$B$44) -> 1000 | O22: =IF(13<6,Assumptions!$B$43,Assumptions!$B$44) -> 1000 | P22: =IF(14<6,Assumptions!$B$43,Assumptions!$B$44) -> 1000 | Q22: =IF(15<6,Assumptions!$B$43,Assumptions!$B$44) -> 1000 | R22: =IF(16<6,Assumptions!$B$43,Assumptions!$B$44) -> 1000 | S22: =IF(17<6,Assumptions!$B$43,Assumptions!$B$44) -> 1000 | T22: =IF(18<6,Assumptions!$B$43,Assumptions!$B$44) -> 1000
A23: Marketing (ramp) | B23: =IF(0<=1,Assumptions!$B$46,IF(0=2,Assumptions!$B$47,IF(0=3,Assumptions!$B$48,Assumptions!$B$49))) -> 750 | C23: =IF(1<=1,Assumptions!$B$46,IF(1=2,Assumptions!$B$47,IF(1=3,Assumptions!$B$48,Assumptions!$B$49))) -> 750 | D23: =IF(2<=1,Assumptions!$B$46,IF(2=2,Assumptions!$B$47,IF(2=3,Assumptions!$B$48,Assumptions!$B$49))) -> 1500 | E23: =IF(3<=1,Assumptions!$B$46,IF(3=2,Assumptions!$B$47,IF(3=3,Assumptions!$B$48,Assumptions!$B$49))) -> 2250 | F23: =IF(4<=1,Assumptions!$B$46,IF(4=2,Assumptions!$B$47,IF(4=3,Assumptions!$B$48,Assumptions!$B$49))) -> 3000 | G23: =IF(5<=1,Assumptions!$B$46,IF(5=2,Assumptions!$B$47,IF(5=3,Assumptions!$B$48,Assumptions!$B$49))) -> 3000 | H23: =IF(6<=1,Assumptions!$B$46,IF(6=2,Assumptions!$B$47,IF(6=3,Assumptions!$B$48,Assumptions!$B$49))) -> 3000 | I23: =IF(7<=1,Assumptions!$B$46,IF(7=2,Assumptions!$B$47,IF(7=3,Assumptions!$B$48,Assumptions!$B$49))) -> 3000 | J23: =IF(8<=1,Assumptions!$B$46,IF(8=2,Assumptions!$B$47,IF(8=3,Assumptions!$B$48,Assumptions!$B$49))) -> 3000 | K23: =IF(9<=1,Assumptions!$B$46,IF(9=2,Assumptions!$B$47,IF(9=3,Assumptions!$B$48,Assumptions!$B$49))) -> 3000 | L23: =IF(10<=1,Assumptions!$B$46,IF(10=2,Assumptions!$B$47,IF(10=3,Assumptions!$B$48,Assumptions!$B$49))) -> 3000 | M23: =IF(11<=1,Assumptions!$B$46,IF(11=2,Assumptions!$B$47,IF(11=3,Assumptions!$B$48,Assumptions!$B$49))) -> 3000 | N23: =IF(12<=1,Assumptions!$B$46,IF(12=2,Assumptions!$B$47,IF(12=3,Assumptions!$B$48,Assumptions!$B$49))) -> 3000 | O23: =IF(13<=1,Assumptions!$B$46,IF(13=2,Assumptions!$B$47,IF(13=3,Assumptions!$B$48,Assumptions!$B$49))) -> 3000 | P23: =IF(14<=1,Assumptions!$B$46,IF(14=2,Assumptions!$B$47,IF(14=3,Assumptions!$B$48,Assumptions!$B$49))) -> 3000 | Q23: =IF(15<=1,Assumptions!$B$46,IF(15=2,Assumptions!$B$47,IF(15=3,Assumptions!$B$48,Assumptions!$B$49))) -> 3000 | R23: =IF(16<=1,Assumptions!$B$46,IF(16=2,Assumptions!$B$47,IF(16=3,Assumptions!$B$48,Assumptions!$B$49))) -> 3000 | S23: =IF(17<=1,Assumptions!$B$46,IF(17=2,Assumptions!$B$47,IF(17=3,Assumptions!$B$48,Assumptions!$B$49))) -> 3000 | T23: =IF(18<=1,Assumptions!$B$46,IF(18=2,Assumptions!$B$47,IF(18=3,Assumptions!$B$48,Assumptions!$B$49))) -> 3000
A24: Variable Opex (subtotal) | B24: =SUM(B19:B23) -> 1750 | C24: =SUM(C19:C23) -> 1750 | D24: =SUM(D19:D23) -> 2500 | E24: =SUM(E19:E23) -> 3250 | F24: =SUM(F19:F23) -> 4000 | G24: =SUM(G19:G23) -> 5500 | H24: =SUM(H19:H23) -> 7500 | I24: =SUM(I19:I23) -> 7500 | ... T24: =SUM(T19:T23) -> 16500
A25: One-Time (legal + SOC2 setup) | B25: =IF(0=0,Assumptions!$B$16+Assumptions!$B$17+Assumptions!$B$18+Assumptions!$B$19,0)+IF(0<Assumptions!$B$21,Assumptions!$B$20/Assumptions!$B$21,0) -> 16666.667 | C25: =IF(1=0,Assumptions!$B$16+Assumptions!$B$17+Assumptions!$B$18+Assumptions!$B$19,0)+IF(1<Assumptions!$B$21,Assumptions!$B$20/Assumptions!$B$21,0) -> 6666.6667 | D25: =IF(2=0,Assumptions!$B$16+Assumptions!$B$17+Assumptions!$B$18+Assumptions!$B$19,0)+IF(2<Assumptions!$B$21,Assumptions!$B$20/Assumptions!$B$21,0) -> 6666.6667 | E25: =IF(3=0,Assumptions!$B$16+Assumptions!$B$17+Assumptions!$B$18+Assumptions!$B$19,0)+IF(3<Assumptions!$B$21,Assumptions!$B$20/Assumptions!$B$21,0) -> 0 | F25: =IF(4=0,Assumptions!$B$16+Assumptions!$B$17+Assumptions!$B$18+Assumptions!$B$19,0)+IF(4<Assumptions!$B$21,Assumptions!$B$20/Assumptions!$B$21,0) -> 0 | G25: =IF(5=0,Assumptions!$B$16+Assumptions!$B$17+Assumptions!$B$18+Assumptions!$B$19,0)+IF(5<Assumptions!$B$21,Assumptions!$B$20/Assumptions!$B$21,0) -> 0 | H25: =IF(6=0,Assumptions!$B$16+Assumptions!$B$17+Assumptions!$B$18+Assumptions!$B$19,0)+IF(6<Assumptions!$B$21,Assumptions!$B$20/Assumptions!$B$21,0) -> 0 | I25: =IF(7=0,Assumptions!$B$16+Assumptions!$B$17+Assumptions!$B$18+Assumptions!$B$19,0)+IF(7<Assumptions!$B$21,Assumptions!$B$20/Assumptions!$B$21,0) -> 0 | J25: =IF(8=0,Assumptions!$B$16+Assumptions!$B$17+Assumptions!$B$18+Assumptions!$B$19,0)+IF(8<Assumptions!$B$21,Assumptions!$B$20/Assumptions!$B$21,0) -> 0 | K25: =IF(9=0,Assumptions!$B$16+Assumptions!$B$17+Assumptions!$B$18+Assumptions!$B$19,0)+IF(9<Assumptions!$B$21,Assumptions!$B$20/Assumptions!$B$21,0) -> 0 | L25: =IF(10=0,Assumptions!$B$16+Assumptions!$B$17+Assumptions!$B$18+Assumptions!$B$19,0)+IF(10<Assumptions!$B$21,Assumptions!$B$20/Assumptions!$B$21,0) -> 0 | M25: =IF(11=0,Assumptions!$B$16+Assumptions!$B$17+Assumptions!$B$18+Assumptions!$B$19,0)+IF(11<Assumptions!$B$21,Assumptions!$B$20/Assumptions!$B$21,0) -> 0 | N25: =IF(12=0,Assumptions!$B$16+Assumptions!$B$17+Assumptions!$B$18+Assumptions!$B$19,0)+IF(12<Assumptions!$B$21,Assumptions!$B$20/Assumptions!$B$21,0) -> 0 | O25: =IF(13=0,Assumptions!$B$16+Assumptions!$B$17+Assumptions!$B$18+Assumptions!$B$19,0)+IF(13<Assumptions!$B$21,Assumptions!$B$20/Assumptions!$B$21,0) -> 0 | P25: =IF(14=0,Assumptions!$B$16+Assumptions!$B$17+Assumptions!$B$18+Assumptions!$B$19,0)+IF(14<Assumptions!$B$21,Assumptions!$B$20/Assumptions!$B$21,0) -> 0 | Q25: =IF(15=0,Assumptions!$B$16+Assumptions!$B$17+Assumptions!$B$18+Assumptions!$B$19,0)+IF(15<Assumptions!$B$21,Assumptions!$B$20/Assumptions!$B$21,0) -> 0 | R25: =IF(16=0,Assumptions!$B$16+Assumptions!$B$17+Assumptions!$B$18+Assumptions!$B$19,0)+IF(16<Assumptions!$B$21,Assumptions!$B$20/Assumptions!$B$21,0) -> 0 | S25: =IF(17=0,Assumptions!$B$16+Assumptions!$B$17+Assumptions!$B$18+Assumptions!$B$19,0)+IF(17<Assumptions!$B$21,Assumptions!$B$20/Assumptions!$B$21,0) -> 0 | T25: =IF(18=0,Assumptions!$B$16+Assumptions!$B$17+Assumptions!$B$18+Assumptions!$B$19,0)+IF(18<Assumptions!$B$21,Assumptions!$B$20/Assumptions!$B$21,0) -> 0
A26: TOTAL CASH OP COST | B26: =B15+B18+B24+B25 -> 20382.667 | C26: =C15+C18+C24+C25 -> 10382.667 | D26: =D15+D18+D24+D25 -> 11132.667 | E26: =E15+E18+E24+E25 -> 5274 | F26: =F15+F18+F24+F25 -> 6081 | G26: =G15+G18+G24+G25 -> 12668 | H26: =H15+H18+H24+H25 -> 14813 | I26: =I15+I18+I24+I25 -> 15016 | ... T26: =T15+T18+T24+T25 -> 29761
A27: CASH — NO SWEEP (hold Joe's loan)
A28: Net Operating Cash Flow | B28: =B13-B26 -> -20382.667 | C28: =C13-C26 -> -10382.667 | D28: =D13-D26 -> -11132.667 | E28: =E13-E26 -> -3284 | F28: =F13-F26 -> -2101 | G28: =G13-G26 -> -5694 | H28: =H13-H26 -> -2849 | I28: =I13-I26 -> 3934 | ... T28: =T13-T26 -> 187292
A29: Joe Loan Drawdown | B29: =IF(0=Assumptions!$B$6,Assumptions!$B$4,0) -> 55000 | C29: =IF(1=Assumptions!$B$6,Assumptions!$B$4,0) -> 0 | D29: =IF(2=Assumptions!$B$6,Assumptions!$B$4,0) -> 0 | E29: =IF(3=Assumptions!$B$6,Assumptions!$B$4,0) -> 0 | F29: =IF(4=Assumptions!$B$6,Assumptions!$B$4,0) -> 0 | G29: =IF(5=Assumptions!$B$6,Assumptions!$B$4,0) -> 0 | H29: =IF(6=Assumptions!$B$6,Assumptions!$B$4,0) -> 0 | I29: =IF(7=Assumptions!$B$6,Assumptions!$B$4,0) -> 0 | J29: =IF(8=Assumptions!$B$6,Assumptions!$B$4,0) -> 0 | K29: =IF(9=Assumptions!$B$6,Assumptions!$B$4,0) -> 0 | L29: =IF(10=Assumptions!$B$6,Assumptions!$B$4,0) -> 0 | M29: =IF(11=Assumptions!$B$6,Assumptions!$B$4,0) -> 0 | N29: =IF(12=Assumptions!$B$6,Assumptions!$B$4,0) -> 0 | O29: =IF(13=Assumptions!$B$6,Assumptions!$B$4,0) -> 0 | P29: =IF(14=Assumptions!$B$6,Assumptions!$B$4,0) -> 0 | Q29: =IF(15=Assumptions!$B$6,Assumptions!$B$4,0) -> 0 | R29: =IF(16=Assumptions!$B$6,Assumptions!$B$4,0) -> 0 | S29: =IF(17=Assumptions!$B$6,Assumptions!$B$4,0) -> 0 | T29: =IF(18=Assumptions!$B$6,Assumptions!$B$4,0) -> 0
A30: Beginning Cash | B30: =0 -> 0 | C30: =B31 -> 34617.333 | D30: =C31 -> 24234.667 | E30: =D31 -> 13102 | F30: =E31 -> 9818 | G30: =F31 -> 7717 | H30: =G31 -> 2023 | I30: =H31 -> -826 | J30: =I31 -> 3108 | ... T30: =S31 -> 762307
A31: ENDING CASH BALANCE | B31: =B30+B28+B29 -> 34617.333 | C31: =C30+C28+C29 -> 24234.667 | D31: =D30+D28+D29 -> 13102 | E31: =E30+E28+E29 -> 9818 | F31: =F30+F28+F29 -> 7717 | G31: =G30+G28+G29 -> 2023 | H31: =H30+H28+H29 -> -826 | I31: =I30+I28+I29 -> 3108 | ... T31: =T30+T28+T29 -> 949599
A32: Cumulative Net Op Cash Flow | B32: =B28 -> -20382.667 | C32: =B32+C28 -> -30765.333 | D32: =C32+D28 -> -41898 | E32: =D32+E28 -> -45182 | F32: =E32+F28 -> -47283 | G32: =F32+G28 -> -52977 | H32: =G32+H28 -> -55826 | I32: =H32+I28 -> -51892 | J32: =I32+J28 -> -40236 | ... T32: =S32+T28 -> 894599
A34: VERDICT — DOES THE BOOTSTRAP SURVIVE?
A35: Peak cumulative cash need | B35: =-MIN(B32:T32) -> 55826 | D35: Deepest hole under this downside
A36: Joe loan needed (peak + buffer) | B36: =-MIN(B32:T32)+Assumptions!$B$7 -> 70826
A37: Min ending cash on base $55k loan | B37: =MIN(B31:T31) -> -826 | D37: Negative => base loan is short
A38: Extra loan needed beyond base | B38: =MAX(0,(-MIN(B32:T32)+Assumptions!$B$7)-Assumptions!$B$4) -> 15826 | D38: Top-up to stay solvent in this case
A39: MRR at Mo 18 (downside) | B39: =T13 -> 217053
A40: Total advisors at Mo 18 (downside) | B40: =T12 -> 447
